Workbook

Sheet ABSENSI PER TMT
B1: DATA ABSENSI SDM YAYASAN BINA INSAN MULIA BATAM PER TMT
B3: 1 | C3: 2 | D3: 3 | E3: 4 | F3: 5 | G3: 7 | H3: 8 | I3: 9 | J3: 10 | K3: 11 | L3: 12 | M3: 13 | N3: 14 | O3: 15 | P3: 16 | Q3: 17 | R3: 18 | S3: 19 | T3: 20 | U3: 21 | V3: 22 | W3: 23 | X3: 24 | Y3: 25 | Z3: 26 | AA3: 27 | AB3: 28 | AC3: 29 | AD3: 30 | AE3: 31 | AF3: 32 | AG3: 33 | AH3: 34 | AI3: 35
A4: No | B4: KODESLIP | C4: NAMA | D4: NRK | E4: UNIT | F4: TTL | G4: JOIN DATE | H4: MASA KERJA | I4: STATUS KARY. | J4: STATUS PERNIKAHAN | K4: PENDIDIKAN | L4: GRADE | M4: GRADE KHUSUS | N4: JABATAN | O4: KODE JABATAN | P4: JML HARI KERJA | Q4: ON TIME | R4: TELAT | S4: SAKIT | T4: IZIN | U4: TANPA KET. | V4: ESKUL PRAMUKA | W4: INST. RENANG | X4: ASST. RENANG | Y4: TUGAS DI HR. KERJA | Z4: TGS. DI HR. LIBUR | AA4: ASST. RENANG | AB4: TAMBAH JAM M'AJAR | AC4: DAYCARE BAYI | AD4: DAY CARE ANAK PG-TK | AE4: MASUK MALAM | AF4: MUSRIF/AH | AG4: NIHIL | AH4: NIHIL | AI4: NIHIL
A5: 1 | B5: SLP001 | C5: KARLINA | D5: 210.0005 | E5: TKIT | F5: Madiun, 21 April 1977 | G5: 40379 | H5: 12 | I5: TETAP | J5: BM | K5: SMA | L5: IA | M5: IA5 | N5: =VLOOKUP(O5,'TJ. FUNGSIONAL'!$B$4:$C$34,2,0) -> Staf Admin RA | O5: ADR
A6: 2 | B6: SLP002 | C6: MUNADIROH | D6: 210.0008 | E6: SDIT | F6: Jember, 12 Desember 1985 | G6: 40379 | H6: 12 | I6: TETAP | J6: M3 | K6: S1 | L6: IIC | M6: IIIA1 | N6: =VLOOKUP(O6,'TJ. FUNGSIONAL'!$B$4:$C$34,2,0) -> Kepala SD | O6: KAD
A7: 3 | B7: SLP003 | C7: ESTI SUSILOWATI | D7: 210.0010 | E7: TKIT | F7: Sleman, 19 Maret 1980 | G7: 40379 | H7: 12 | I7: TETAP | J7: M3 | K7: S1 | L7: IC | M7: IIA1 | N7: =VLOOKUP(O7,'TJ. FUNGSIONAL'!$B$4:$C$34,2,0) -> Kepala RA | O7: KAR
A8: 4 | B8: SLP004 | C8: DORIOMAS | D8: 210.0013 | E8: TKIT | F8: Purba Bangun, 01 April 1971 | G8: 40379 | H8: 12 | I8: TETAP | J8: M5 | K8: SMA | L8: IA | M8: IA5 | N8: =VLOOKUP(O8,'TJ. FUNGSIONAL'!$B$4:$C$34,2,0) -> Petugas Kebersihan | O8: PKR
A9: 5 | B9: SLP005 | C9: SITI MUTOFIAH | D9: 210.0017 | E9: TKIT | F9: Nganjuk 19-12-1986 | G9: 40513 | H9: 11 | I9: TETAP | J9: M2 | K9: S1 | L9: IC | M9: IC5 | N9: =VLOOKUP(O9,'TJ. FUNGSIONAL'!$B$4:$C$34,2,0) -> Wakil Kepala RA | O9: WAR
A10: 6 | B10: SLP006 | C10: SITI MASITOH | D10: 211.0020 | E10: SDIT | F10: Lamongan, 06-06-1980 | G10: 40716 | H10: 11 | I10: TETAP | J10: M5 | K10: S1 | L10: IB | M10: IB5 | N10: =VLOOKUP(O10,'TJ. FUNGSIONAL'!$B$4:$C$34,2,0) -> Wakil Kepala SD | O10: WAD
A11: 7 | B11: SLP007 | C11: NANIK SRIYANI | D11: 212.0030 | E11: SDIT | F11: Karanganyar, 06-02-1983 | G11: 41094 | H11: 10 | I11: TETAP | J11: M1 | K11: S1 | L11: IIB | M11: IIB7 | N11: =VLOOKUP(O11,'TJ. FUNGSIONAL'!$B$4:$C$34,2,0) -> Kepala Divisi | O11: KDV
A12: 8 | B12: SLP008 | C12: JENI ABDUL AZIZ | D12: 213.0037 | E12: SDIT | F12: Tasikmalaya, 08-02-1991 | G12: 41465 | H12: 9 | I12: TETAP | J12: BM | K12: S1 | L12: IIB | M12: IIB7 | N12: =VLOOKUP(O12,'TJ. FUNGSIONAL'!$B$4:$C$34,2,0) -> Kepala Divisi | O12: KDV
A13: 9 | B13: SLP009 | C13: SURYANA | D13: 214.0054 | E13: SMPIT | F13: Tembilahan, 12-09-1989 | G13: 41834 | H13: 8 | I13: TETAP | J13: BM | K13: S1 | L13: IIB | M13: IIB10 | N13: =VLOOKUP(O13,'TJ. FUNGSIONAL'!$B$4:$C$34,2,0) -> Wakil Kepala SMP | O13: WAP
A14: 10 | B14: SLP010 | C14: JUMAINI | D14: 214.0064 | E14: TKIT | F14: Desa Bantan, 21-01-1984 | G14: 41871 | H14: 7 | I14: TETAP | J14: M3 | K14: SMA | L14: IA | M14: IA5 | N14: =VLOOKUP(O14,'TJ. FUNGSIONAL'!$B$4:$C$34,2,0) -> Karywn Penitipan | O14: KYP
A15: 11 | B15: SLP011 | C15: ERLINA SAGALA | D15: 215.0065 | E15: SMPIT | F15: Jumah, 16-06-1984 | G15: 42122 | H15: 7 | I15: TETAP | J15: BM | K15: SMA | L15: IB | M15: IC1 | N15: =VLOOKUP(O15,'TJ. FUNGSIONAL'!$B$4:$C$34,2,0) -> Wakil Kepala SMP | O15: WAP
A16: 12 | B16: SLP012 | C16: AYEP | D16: 216.0084 | E16: SDIT | F16: Bandung, 10-04-1992 | G16: 42591 | H16: 5 | I16: TETAP | J16: BM | K16: S1 | L16: IB | M16: IC5 | N16: =VLOOKUP(O16,'TJ. FUNGSIONAL'!$B$4:$C$34,2,0) -> Wakil Kepala SD | O16: WAD
... A25: 21 | B25: SLP021 | C25: ARIS WIDARSO | D25: 218.0116 | E25: SDIT | F25: Kendal, 19 Januari 1993 | G25: 43297 | H25: 4 | I25: TETAP | J25: BM | K25: S1 | L25: IC | M25: IC5 | N25: =VLOOKUP(O25,'TJ. FUNGSIONAL'!$B$4:$C$34,2,0) -> Wakil Kepala SD | O25: WADD
A26: 22 | B26: SLP022 | C26: NOVITA PUTRI FATMA | D26: 218.0120 | E26: TKIT | F26: Sidoarjo, 08 September 2000 | G26: 20-Agust-2018 | H26: 3 | I26: KONTRAK | J26: BM | K26: SMA | L26: IA | M26: IB1 | N26: =VLOOKUP(O26,'TJ. FUNGSIONAL'!$B$4:$C$34,2,0) -> Wali Kelas RA | O26: WKR
A27: 23 | B27: SLP023 | C27: IZA FARIDATUL AMALIA | D27: 218.0119 | E27: TKIT | F27: Jember, 14 Oktober 2000 | G27: 43346 | H27: 3 | I27: KONTRAK | J27: BM | K27: SMA | L27: IA | M27: IA1 | N27: =VLOOKUP(O27,'TJ. FUNGSIONAL'!$B$4:$C$34,2,0) -> Wakil Kepala RA | O27: WAR
A28: 24 | B28: SLP024 | C28: LISTIA NURULITA | D28: 219.0126 | E28: YAYASAN | F28: Banyumas, 7 Maret 1979 | G28: 43600 | H28: 2 | I28: KONTRAK | J28: M5 | K28: SMA | L28: IB | M28: IC1 | N28: =VLOOKUP(O28,'TJ. FUNGSIONAL'!$B$4:$C$34,2,0) -> Staf Yayasan | O28: SAY
A29: 25 | B29: SLP025 | C29: WIDIYANTI | D29: 219.0136 | E29: SDIT | F29: Pekauman Kulon, 16 Juni 1990 | G29: 15 Oktober 2019 | H29: 2 | I29: KONTRAK | J29: BM | K29: S1 | L29: IC | M29: IC1 | N29: =VLOOKUP(O29,'TJ. FUNGSIONAL'!$B$4:$C$34,2,0) -> Wakil Kepala SD | O29: WADD
A30: 26 | B30: SLP026 | C30: ADE PIRDANA P | D30: 219.0140 | E30: SDIT | F30: Kumpulan, 23 Desember 1993 | G30: 15 Oktober 2019 | H30: 2 | I30: KONTRAK | J30: BM | K30: S1 | L30: IB | M30: IB5 | N30: =VLOOKUP(O30,'TJ. FUNGSIONAL'!$B$4:$C$34,2,0) -> Guru Mapel SD | O30: GMD
A31: 27 | B31: SLP027 | C31: SRI INDRA WAHYUNI | D31: 219.0137 | E31: SDIT | F31: Dumai, 01 September 1994 | G31: 15 Oktober 2019 | H31: 2 | I31: KONTRAK | J31: BM | K31: S2 | L31: IC | M31: IIA1 | N31: =VLOOKUP(O31,'TJ. FUNGSIONAL'!$B$4:$C$34,2,0) -> Wakil Kepala SD | O31: wadd
A32: 28 | B32: SLP028 | C32: MOCHAMAD TOYIB | D32: 219.0141 | E32: SDIT | F32: Batam, 31 Juli 1997 | G32: 19 Oktober 2019 | H32: 2 | I32: KONTRAK | J32: M1 | K32: SMA | L32: IA | M32: IA7 | N32: =VLOOKUP(O32,'TJ. FUNGSIONAL'!$B$4:$C$34,2,0) -> Petugas Keamanan | O32: PKY
A33: 29 | B33: SLP029 | C33: DESI MUTIARA | D33: 219.0145 | E33: SDIT | F33: Prabumulih, 22 Desember 1995 | G33: 43780 | H33: 2 | I33: KONTRAK | J33: BM | K33: S1 | L33: IB | M33: IB5 | N33: =VLOOKUP(O33,'TJ. FUNGSIONAL'!$B$4:$C$34,2,0) -> Wali Kelas SD | O33: WKD
A34: 30 | B34: SLP030 | C34: ANDY | D34: 220.0146 | E34: SDIT | F34: Batam, 8 Januari 1996 | G34: 3 Januari 2020 | H34: 2 | I34: KONTRAK | J34: M2 | K34: SMA | L34: IA | M34: IA1 | N34: =VLOOKUP(O34,'TJ. FUNGSIONAL'!$B$4:$C$34,2,0) -> Petugas Keamanan | O34: PKY
A35: 31 | B35: SLP031 | C35: DENNI SUKMA | D35: 220.0148 | E35: SDIT | F35: Padang, 22 Januari 1986 | G35: 3 Februari 2020 | H35: 2 | I35: KONTRAK | J35: M2 | K35: S1 | L35: IB | M35: IB5 | N35: =VLOOKUP(O35,'TJ. FUNGSIONAL'!$B$4:$C$34,2,0) -> Wali Kelas SD | O35: WKD
A36: 32 | B36: SLP032 | C36: CICI HAFSHAH SIPAHUTAR | D36: 220.0149 | E36: SDIT | F36: Bandar Selamat, 11 Oktober 1992 | G36: 3 Februari 2020 | H36: 2 | I36: KONTRAK | J36: M0 | K36: S2 | L36: IC | M36: IC7 | N36: =VLOOKUP(O36,'TJ. FUNGSIONAL'!$B$4:$C$34,2,0) -> Guru Mapel SD | O36: GMD
A37: 33 | B37: SLP033 | C37: ELSI ERIES SANTI | D37: 220.0151 | E37: SDIT | F37: Teluk Kuantan,13 September 1991 | G37: 24 Februari 2020 | H37: 2 | I37: KONTRAK | J37: M0 | K37: S1 | L37: IB | M37: IB7 | N37: =VLOOKUP(O37,'TJ. FUNGSIONAL'!$B$4:$C$34,2,0) -> Wali Kelas SD | O37: WKD
A38: 34 | B38: SLP034 | C38: DEWI PRATIWI | D38: 220.0152 | E38: SDIT | F38: Tangkahan Durian, 5 Desember 1995 | G38: 25 Februari 2020 | H38: 2 | I38: KONTRAK | J38: BM | K38: S1 | L38: IB | M38: IC1 | N38: =VLOOKUP(O38,'TJ. FUNGSIONAL'!$B$4:$C$34,2,0) -> Wakil Kepala SD | O38: wadd
A39: 35 | B39: SLP035 | C39: HANNA NUR HAFAZAH | D39: 220.0155 | E39: SMPIT | F39: DKI Jakarta, 14 Agustus 1995 | G39: 6 Juli 2020 | H39: 2 | I39: KONTRAK | J39: M0 | K39: S-1 | L39: IB | M39: IB7 | N39: =VLOOKUP(O39,'TJ. FUNGSIONAL'!$B$4:$C$34,2,0) -> Guru Quran SMP | O39: GQP
A40: 36 | B40: SLP036 | C40: SUSI MARLITA | D40: 220.0157 | E40: SDIT | F40: Medan, 31 Maret 1978 | G40: 7 Oktober 2020 | H40: 1 | I40: KONTRAK | J40: BM | K40: D-3 | L40: IB | M40: IB3 | N40: =VLOOKUP(O40,'TJ. FUNGSIONAL'!$B$4:$C$34,2,0) -> Guru Quran SD | O40: GQD
A41: 37 | B41: SLP037 | C41: ESA YUSUF EFFENDI | D41: 221.0163 | E41: SDIT | F41: Tanjung Uban, 28 September 1999 | G41: 11 Juli 2021 | H41: 1 | I41: KONTRAK | J41: BM | K41: SMA | L41: IA | M41: IA1 | N41: =VLOOKUP(O41,'TJ. FUNGSIONAL'!$B$4:$C$34,2,0) -> Guru Quran SD | O41: GQD
A42: 38 | B42: SLP038 | C42: RAMA SATRIA | D42: 221.0165 | E42: SDIT | F42: Lahat, 16 Juli 1999 | G42: 11 Juli 2021 | H42: 1 | I42: KONTRAK | J42: BM | K42: SMA | L42: IA | M42: IA1 | N42: =VLOOKUP(O42,'TJ. FUNGSIONAL'!$B$4:$C$34,2,0) -> Guru Quran SD | O42: GQD
A43: 39 | B43: SLP039 | C43: RIKHA IKKE NURIANI | D43: 221.0170 | E43: SDIT | F43: Batam, 25 Juli 1998 | G43: 11 Juli 2021 | H43: 1 | I43: KONTRAK | J43: BM | K43: S1 | L43: IB | M43: IC1 | N43: =VLOOKUP(O43,'TJ. FUNGSIONAL'!$B$4:$C$34,2,0) -> Guru Mapel SD | O43: GMD
A44: 40 | B44: SLP040 | C44: NUR MEILISA PUTRI | D44: 221.0173 | E44: SDIT | F44: Gebang, 17 Mei 1998 | G44: 11 Juli 2021 | H44: 1 | I44: KONTRAK | J44: M2 | K44: S1 | L44: IB | M44: IC1 | N44: =VLOOKUP(O44,'TJ. FUNGSIONAL'!$B$4:$C$34,2,0) -> Guru Quran SD | O44: GQD
A45: 41 | B45: SLP041 | C45: FARHANI AL ZIKRA | D45: 221.0178 | E45: SMPIT | F45: Kuantan Pahang, Malaysia, 12 Desember 1997 | G45: 44457 | H45: 0 | I45: KONTRAK | J45: BM | K45: S-1 | L45: IB | M45: IC1 | N45: =VLOOKUP(O45,'TJ. FUNGSIONAL'!$B$4:$C$34,2,0) -> Guru Mapel SMP | O45: GMP
A46: 42 | B46: SLP042 | C46: JAMALIANDA SAPUTRA | D46: 221.0180 | E46: SDIT | F46: Tanah Merah, 25 Januari 2001 | G46: 44508 | H46: 0 | I46: KONTRAK | J46: BM | K46: SMA | L46: IA | M46: IA1 | N46: =VLOOKUP(O46,'TJ. FUNGSIONAL'!$B$4:$C$34,2,0) -> Guru Quran SD | O46: GQD
A47: 43 | B47: SLP043 | C47: DEVI SEPTRIANA | D47: 221.0181 | E47: SDIT | F47: Batam, 1 September 1998 | G47: 44508 | H47: 0 | I47: KONTRAK | J47: BM | K47: SMA | L47: IA | M47: IA1 | N47: =VLOOKUP(O47,'TJ. FUNGSIONAL'!$B$4:$C$34,2,0) -> Guru Quran SD | O47: GQD
A48: 44 | B48: SLP044 | C48: EMILIA | D48: 222.0182 | E48: SDIT | F48: Aceh, 26 Agustus 1973 | G48: 14 Februari 2022 | H48: 0 | I48: KONTRAK | J48: M3 | K48: SMA | L48: 1A | M48: 1A1 | N48: =VLOOKUP(O48,'TJ. FUNGSIONAL'!$B$4:$C$34,2,0) -> Petugas Dapur | O48: PDY
A49: 45 | B49: SLP045 | C49: SRI ASTUTI | D49: 222.0183 | E49: SDIT | F49: Minta Kasih, 12 Mei 1980 | G49: 14 Februari 2022 | H49: 0 | I49: KONTRAK | J49: M2 | K49: SMA | L49: 1A | M49: 1A1 | N49: =VLOOKUP(O49,'TJ. FUNGSIONAL'!$B$4:$C$34,2,0) -> Petugas Dapur | O49: PDY
...

Sheet Gapok
A4: Lulus | B4: Grade | C4: Gapok | D4: selisih | E4: Tj Hadir | F4: Tj Hdr 1bulan | G4: Gapok 2 | H4: Tj Hadir | I4: Tj Hdr 1bulan
A5: SMA | B5: IA1 | C5: 800000 | D5: 20000 | E5: 15000 | F5: 375000 | G5: 800000 | H5: 15000 | I5: 375000
B6: IA2 | C6: 820000 | D6: 20000 | E6: 15000 | F6: 375000 | G6: =G5+25000 -> 825000 | H6: 15000 | I6: 375000
B7: IA3 | C7: 840000 | D7: 20000 | E7: 15000 | F7: 375000 | G7: =G6+25000 -> 850000 | H7: 15000 | I7: 375000
B8: IA4 | C8: 860000 | D8: 20000 | E8: 15000 | F8: 375000 | G8: =G7+25000 -> 875000 | H8: 15000 | I8: 375000
B9: IA5 | C9: 880000 | D9: 20000 | E9: 15000 | F9: 375000 | G9: =G8+25000 -> 900000 | H9: 15000 | I9: 375000
B10: IA6 | C10: 900000 | D10: 20000 | E10: 15000 | F10: 375000 | G10: =G9+25000 -> 925000 | H10: 15000 | I10: 375000
B11: IA7 | C11: 920000 | D11: 20000 | E11: 15000 | F11: 375000 | G11: =G10+25000 -> 950000 | H11: 15000 | I11: 375000
B12: IA8 | C12: 940000 | D12: 20000 | E12: 15000 | F12: 375000 | G12: =G11+25000 -> 975000 | H12: 15000 | I12: 375000
B13: IA9 | C13: 960000 | D13: 20000 | E13: 15000 | F13: 375000 | G13: =G12+25000 -> 1000000 | H13: 15000 | I13: 375000
B14: IA10 | C14: 980000 | D14: 20000 | E14: 15000 | F14: 375000 | G14: =G13+25000 -> 1025000 | H14: 15000 | I14: =H14*25 -> 375000
B15: IB1 | C15: 930000 | D15: 10000 | E15: 15000 | F15: 375000 | G15: =G14+50000 -> 1075000 | H15: 16000 | I15: =H15*25 -> 400000
B16: IB2 | C16: 950000 | D16: 20000 | E16: 15000 | F16: 375000 | G16: =G15+25000 -> 1100000 | H16: 16000 | I16: =H16*25 -> 400000
B17: IB3 | C17: 970000 | D17: 20000 | E17: 15000 | F17: 375000 | G17: =G16+25000 -> 1125000 | H17: 16000 | I17: =H17*25 -> 400000
B18: IB4 | C18: 990000 | D18: 20000 | E18: 15000 | F18: 375000 | G18: =G17+25000 -> 1150000 | H18: 16000 | I18: =H18*25 -> 400000
B19: IB5 | C19: 1010000 | D19: 20000 | E19: 15000 | F19: 375000 | G19: =G18+25000 -> 1175000 | H19: 16000 | I19: =H19*25 -> 400000
B20: IB6 | C20: 1030000 | D20: 20000 | E20: 15000 | F20: 375000 | G20: =G19+25000 -> 1200000 | H20: 16000 | I20: =H20*25 -> 400000
B21: IB7 | C21: 1050000 | D21: 20000 | E21: 15000 | F21: 375000 | G21: =G20+25000 -> 1225000 | H21: 16000 | I21: =H21*25 -> 400000
B22: IB8 | C22: 1070000 | D22: 20000 | E22: 15000 | F22: 375000 | G22: =G21+25000 -> 1250000 | H22: 16000 | I22: =H22*25 -> 400000
B23: IB9 | C23: 1090000 | D23: 20000 | E23: 15000 | F23: 375000 | G23: =G22+25000 -> 1275000 | H23: 16000 | I23: =H23*25 -> 400000
B24: IB10 | C24: 1110000 | D24: 20000 | E24: 15000 | F24: 375000 | G24: =G23+25000 -> 1300000 | H24: 16000 | I24: =H24*25 -> 400000
A25: SMA+S1 | B25: IC1 | C25: 1020000 | D25: -30000 | E25: 15000 | F25: 375000 | G25: =G24+50000 -> 1350000 | H25: 17000 | I25: =H25*25 -> 425000
B26: IC2 | C26: 1040000 | D26: 20000 | E26: 15000 | F26: 375000 | G26: =G25+25000 -> 1375000 | H26: 17000 | I26: =H26*25 -> 425000
B27: IC3 | C27: 1060000 | D27: 20000 | E27: 15000 | F27: 375000 | G27: =G26+25000 -> 1400000 | H27: 17000 | I27: =H27*25 -> 425000
B28: IC4 | C28: 1080000 | D28: 20000 | E28: 15000 | F28: 375000 | G28: =G27+25000 -> 1425000 | H28: 17000 | I28: =H28*25 -> 425000
B29: IC5 | C29: 1100000 | D29: 20000 | E29: 15000 | F29: 375000 | G29: =G28+25000 -> 1450000 | H29: 17000 | I29: =H29*25 -> 425000
B30: IC6 | C30: 1120000 | D30: 20000 | E30: 15000 | F30: 375000 | G30: =G29+25000 -> 1475000 | H30: 17000 | I30: =H30*25 -> 425000
B31: IC7 | C31: 1140000 | D31: 20000 | E31: 15000 | F31: 375000 | G31: =G30+25000 -> 1500000 | H31: 17000 | I31: =H31*25 -> 425000
B32: IC8 | C32: 1160000 | D32: 20000 | E32: 15000 | F32: 375000 | G32: =G31+25000 -> 1525000 | H32: 17000 | I32: =H32*25 -> 425000
B33: IC9 | C33: 1180000 | D33: 20000 | E33: 15000 | F33: 375000 | G33: =G32+25000 -> 1550000 | H33: 17000 | I33: =H33*25 -> 425000
B34: IC10 | C34: 1200000 | D34: 20000 | E34: 15000 | F34: 375000 | G34: =G33+25000 -> 1575000 | H34: 17000 | I34: =H34*25 -> 425000
A35: S1 + S2 | B35: IIA1 | C35: 1190000 | D35: 50000 | E35: 17500 | F35: 437500 | G35: =G34+75000 -> 1650000 | H35: 18000 | I35: =H35*25 -> 450000
B36: IIA2 | C36: 1215000 | D36: 25000 | E36: 17500 | F36: 437500 | G36: =G35+25000 -> 1675000 | H36: 18000 | I36: =H36*25 -> 450000
B37: IIA3 | C37: 1240000 | D37: 25000 | E37: 17500 | F37: 437500 | G37: =G36+25000 -> 1700000 | H37: 18000 | I37: =H37*25 -> 450000
B38: IIA4 | C38: 1265000 | D38: 25000 | E38: 17500 | F38: 437500 | G38: =G37+25000 -> 1725000 | H38: 18000 | I38: =H38*25 -> 450000
B39: IIA5 | C39: 1290000 | D39: 25000 | E39: 17500 | F39: 437500 | G39: =G38+25000 -> 1750000 | H39: 18000 | I39: =H39*25 -> 450000
B40: IIA6 | C40: 1315000 | D40: 25000 | E40: 17500 | F40: 437500 | G40: =G39+25000 -> 1775000 | H40: 18000 | I40: =H40*25 -> 450000
B41: IIA7 | C41: 1340000 | D41: 25000 | E41: 17500 | F41: 437500 | G41: =G40+25000 -> 1800000 | H41: 18000 | I41: =H41*25 -> 450000
B42: IIA8 | C42: 1365000 | D42: 25000 | E42: 17500 | F42: 437500 | G42: =G41+25000 -> 1825000 | H42: 18000 | I42: =H42*25 -> 450000
B43: IIA9 | C43: 1390000 | D43: 25000 | E43: 17500 | F43: 437500 | G43: =G42+25000 -> 1850000 | H43: 18000 | I43: =H43*25 -> 450000
...

Sheet SLIP GAJI
A2: YAYASAN BINA INSAN MULIA BATAM - SLIP GAJI KARYAWAN | N2: SLIP | O2: SLP005
A3: SEKOLAH ISLAM TERPADU MUTIARA INSANI BATAM
A5: NAMA | B5: : | C5: =VLOOKUP($O$2,#REF!,2,0) -> #REF! | H5: BULAN | I5: : | J5: =VLOOKUP($O$2,#REF!,6,0) -> #REF!
A6: NRK | B6: : | C6: =VLOOKUP($O$2,#REF!,3,0) -> #REF! | H6: JML HARI KERJA | I6: : | J6: =VLOOKUP($O$2,#REF!,16,0) -> #REF! | K6: hari
A7: UNIT | B7: : | C7: =VLOOKUP($O$2,#REF!,4,0) -> #REF! | H7: TEPAT WAKTU | I7: : | J7: =VLOOKUP($O$2,#REF!,17,0) -> #REF! | K7: hari
A8: JABATAN | B8: : | C8: =VLOOKUP($O$2,#REF!,14,0) -> #REF! | H8: TERLAMBAT | I8: : | J8: =VLOOKUP($O$2,#REF!,18,0) -> #REF! | K8: hari
A9: TMT | B9: : | C9: =VLOOKUP($O$2,#REF!,7,0) -> #REF! | H9: SAKIT | I9: : | J9: =VLOOKUP($O$2,#REF!,19,0) -> #REF! | K9: hari
A10: DCR RA | B10: : | H10: IZIN | I10: : | J10: =VLOOKUP($O$2,#REF!,20,0) -> #REF! | K10: hari
A11: DCR SD | B11: : | H11: TANPA KET. | I11: : | J11: =VLOOKUP($O$2,#REF!,21,0) -> #REF! | K11: hari
H13: POTONGAN-POTONGAN
A14: GJ. POKOK | D14: : | E14: =VLOOKUP($O$2,#REF!,36,0) -> #REF! | H14: POT. ABSEN | I14: : | J14: =VLOOKUP($O$2,#REF!,54,0) -> #REF!
A15: TJ. FUNGSIONAL | D15: : | E15: =VLOOKUP($O$2,#REF!,37,0) -> #REF! | H15: POT. TELAT | I15: : | J15: =VLOOKUP($O$2,#REF!,55,0) -> #REF!
A16: TJ. KEHADIRAN | D16: : | E16: =VLOOKUP($O$2,#REF!,38,0) -> #REF! | H16: POT. DAYCARE | I16: : | J16: =VLOOKUP($O$2,#REF!,56,0) -> #REF!
A17: TJ. RUMAH | D17: : | E17: =VLOOKUP($O$2,#REF!,39,0) -> #REF! | H17: POT. BPJS | I17: : | J17: =VLOOKUP($O$2,#REF!,57,0) -> #REF!
A18: TJ. MASA KERJA | D18: : | E18: =VLOOKUP($O$2,#REF!,40,0) -> #REF! | H18: POT. PINJAMAN | I18: : | J18: =VLOOKUP($O$2,#REF!,58,0) -> #REF!
A19: TJ . BPJS KESEHATAN | D19: : | E19: =VLOOKUP($O$2,#REF!,41,0) -> #REF! | H19: POT. KADO | J19: =VLOOKUP($O$2,#REF!,59,0) -> #REF!
A20: SUBSIDI DAYCARE | D20: : | E20: =VLOOKUP($O$2,#REF!,41,0) -> #REF!
A21: TJ. TAMBAHAN | D21: : | E21: =VLOOKUP($O$2,#REF!,47,0) -> #REF! | H21: TTL. POTONGAN | I21: : | J21: =VLOOKUP($O$2,#REF!,65,0) -> #REF!
A22: KET TJ TAMBAHAN | D22: : | E22: =VLOOKUP($O$2,#REF!,48,0) -> #REF! | H22: KOREKSI | I22: : | J22: =VLOOKUP($O$2,#REF!,66,0) -> #REF!
A25: GAJI UTAMA | D25: : | E25: =VLOOKUP($O$2,#REF!,53,0) -> #REF! | H25: GAJI BERSIH | I25: : | J25: =VLOOKUP($O$2,#REF!,68,0) -> #REF!
A29: RIWAYAT PINJAMAN | D29: :
A30: TANGGAL | D30: : | E30: =VLOOKUP($O$2,#REF!,71,0) -> #REF!
A31: BESAR PINJAMAN | D31: : | E31: =VLOOKUP($O$2,#REF!,72,0) -> #REF!
A32: LAMA ANGSURAN | D32: : | E32: =VLOOKUP($O$2,#REF!,73,0) -> #REF!
A33: BESAR ANGSURAN | D33: : | E33: =VLOOKUP($O$2,#REF!,74,0) -> #REF!
A34: BLN TRAKHIR ANGSURAN | D34: : | E34: =VLOOKUP($O$2,#REF!,75,0) -> #REF!
A35: SISA PINJAMAN | D35: : | E35: =VLOOKUP($O$2,#REF!,76,0) -> #REF!
A38: Keterangan Pot Kado | D38: : | E38: 0
A40: Keterangan Koreksi | D40: : | E40: 0
A51: JUMLAH HARI | B51: JML HARI KERJA | D51: 19
B52: MASUK | D52: =D53+D54 -> 19
B53: TEPAT WAKTU | D53: 19
B54: TELAT | D54: 0
B55: ABSEN | D55: 0
B56: TGS. HR. KERJA | D56: 0
B57: TGS. HR. LIBUR | D57: 3
B58: DAYCARE BAYI | D58: 0
B59: DAYCARE PAUD | D59: 0

Sheet TJ. FUNGSIONAL
A1: Besar Tunjangan Fungsional
D2: GURU BARU | F2: GURU LAMA
A3: Unit | B3: Kode | C3: Jb. Fungsional | D3: Tj. Fungsional | E3: TJ.R | F3: Tj Fungsional 2
A4: RA | B4: KYP | C4: Karywn Penitipan | D4: 400000 | E4: 300000 | F4: 400000 | G4: =F4-D4 -> 0
B5: PKR | C5: Petugas Kebersihan | D5: 400000 | E5: 300000 | F5: 400000 | G5: =F5-D5 -> 0
B6: ADR | C6: Staf Admin RA | D6: 400000 | E6: 300000 | F6: 400000 | G6: =F6-D6 -> 0
B7: GKR | C7: Guru Kelas RA | D7: 500000 | E7: 300000 | F7: 500000 | G7: =F7-D7 -> 0
B8: WKR | C8: Wali Kelas RA | D8: 600000 | E8: 300000 | F8: 700000 | G8: =F8-D8 -> 100000
B9: WAR | C9: Wakil Kepala RA | D9: 900000 | E9: 400000 | F9: 1200000 | G9: =F9-D9 -> 300000
B10: KAR | C10: Kepala RA | D10: 1200000 | E10: 500000 | F10: 1500000 | G10: =F10-D10 -> 300000
A11: SD | B11: PKD | C11: Petugas Kebersihan | D11: 400000 | E11: 300000 | F11: 400000 | G11: =F11-D11 -> 0
B12: GQD | C12: Guru Quran SD | D12: 800000 | E12: 300000 | F12: 900000 | G12: =F12-D12 -> 100000
B13: GKD | C13: Guru Kelas SD | D13: 900000 | E13: 300000 | F13: 900000 | G13: =F13-D13 -> 0
B14: WKD | C14: Wali Kelas SD | D14: 1200000 | E14: 300000 | F14: 1200000 | G14: =F14-D14 -> 0
B15: GMD | C15: Guru Mapel SD | D15: 900000 | E15: 300000 | F15: 900000 | G15: =F15-D15 -> 0
B16: ADD | C16: Staf Admin SD | D16: 600000 | E16: 300000 | F16: 600000 | G16: =F16-D16 -> 0
B17: WAD | C17: Wakil Kepala SD | D17: 1700000 | E17: 500000 | F17: 1700000 | G17: =F17-D17 -> 0
B18: WADD | C18: Wakil Kepala SD | D18: 1500000 | E18: 400000 | F18: 1500000 | G18: =F18-D18 -> 0
B19: KAD | C19: Kepala SD | D19: 2200000 | E19: 750000 | F19: 2200000 | G19: =F19-D19 -> 0
A20: SMP | B20: PKP | C20: Petugas Kebersihan | D20: 400000 | E20: 300000 | F20: 400000 | G20: =F20-D20 -> 0
B21: GQP | C21: Guru Quran SMP | D21: 900000 | E21: 300000 | F21: 1000000 | G21: =F21-D21 -> 100000
B22: GQM | C22: Guru Quran SMP dan Musyrif | D22: 1150000 | F22: 1250000 | G22: =F22-D22 -> 100000
B23: WKP | C23: Wali Kelas SMP | D23: 1200000 | E23: 300000 | F23: 1200000 | G23: =F23-D23 -> 0
B24: GMP | C24: Guru Mapel SMP | D24: 900000 | E24: 300000 | F24: 900000 | G24: =F24-D24 -> 0
B25: GMM | C25: GuruMapel SMP dan Musyrif | D25: 1150000 | F25: 1300000 | G25: =F25-D25 -> 150000
B26: ADP | C26: Staf Admin SMP | D26: 600000 | E26: 300000 | F26: 600000 | G26: =F26-D26 -> 0
B27: WAP | C27: Wakil Kepala SMP | D27: 1700000 | E27: 500000 | F27: 2000000 | G27: =F27-D27 -> 300000
B28: KAP | C28: Kepala SMP | D28: 2200000 | E28: 750000 | F28: 2300000 | G28: =F28-D28 -> 100000
A29: YAYASAN | B29: PKY | C29: Petugas Keamanan | D29: 1200000 | E29: 300000 | F29: 1200000 | G29: =F29-D29 -> 0
B30: SAY | C30: Staf Yayasan | D30: 1300000 | E30: 500000 | F30: 1300000 | G30: =F30-D30 -> 0
B31: ADY | C31: Staf Admin Yayasan | D31: 850000 | E31: 300000 | F31: 850000 | G31: =F31-D31 -> 0
B32: PDY | C32: Petugas Dapur | D32: 450000 | E32: 300000 | F32: 450000 | G32: =F32-D32 -> 0
B33: KDP | C33: Kepala Deputi | D33: 2300000 | E33: 750000 | F33: 2500000 | G33: =F33-D33 -> 200000
B34: KDV | C34: Kepala Divisi | D34: 1850000 | E34: 750000 | F34: 2200000 | G34: =F34-D34 -> 350000

Sheet POTONGAN BPJS JHT
A1: No | B1: Nama | C1: Besar angsuran BPJS Ketenagakerjaan
C2: Februari | D2: Maret | E2: April | F2: Mei | G2: Juni | H2: Juli | I2: Agustus | J2: September | K2: Oktober | L2: November | M2: Desember | N2: Desember | O2: Februari | P2: Maret
A3: 1 | B3: Rika | C3: 100000 | D3: 140000 | E3: 140000 | F3: 140000 | G3: 40000 | H3: 40000 | I3: 40000 | J3: 40000 | K3: 40000 | L3: 40000 | M3: 40000 | N3: 40000 | O3: 40000 | P3: 40000
A4: 2 | B4: Cici | C4: 100000 | D4: 140000 | E4: 140000 | F4: 140000 | G4: 40000 | H4: 40000 | I4: 40000 | J4: 40000 | K4: 40000 | L4: 40000 | M4: 40000 | N4: 40000 | O4: 40000 | P4: 40000
A5: 3 | B5: Ade | C5: 100000 | D5: 140000 | E5: 140000 | F5: 140000 | G5: 40000 | H5: 40000 | I5: 40000 | J5: 40000 | K5: 40000 | L5: 40000 | M5: 40000 | N5: 40000 | O5: 40000 | P5: 40000
A6: 4 | B6: Atikah | C6: 100000 | D6: 140000 | E6: 140000 | F6: 140000 | G6: 40000 | H6: 40000 | I6: 40000 | J6: 40000 | K6: 40000 | L6: 40000 | M6: 40000 | N6: 40000 | O6: 40000 | P6: 40000
A7: 5 | B7: Nanik | C7: 100000 | D7: 140000 | E7: 140000 | F7: 140000 | G7: 40000 | H7: 40000 | I7: 40000 | J7: 40000 | K7: 40000 | L7: 40000 | M7: 40000 | N7: 40000 | O7: 40000 | P7: 40000
A8: 6 | B8: Ayep | C8: 100000 | D8: 140000 | E8: 140000 | F8: 140000 | G8: 40000 | H8: 40000 | I8: 40000 | J8: 40000 | K8: 40000 | L8: 40000 | M8: 40000 | N8: 40000 | O8: 40000 | P8: 40000
A9: 7 | B9: Tri | C9: 100000 | D9: 140000 | E9: 140000 | F9: 140000 | G9: 40000 | H9: 40000 | I9: 40000 | J9: 40000 | K9: 40000 | L9: 40000 | M9: 40000 | N9: 40000 | O9: 40000 | P9: 40000
A10: 8 | B10: Aris | C10: 400000 | D10: iuran rutin | E10: iuran rutin | F10: iuran rutin | G10: 40000 | H10: 40000 | I10: 40000 | J10: 40000 | K10: 40000 | L10: 40000 | M10: 40000 | N10: 40000 | O10: 40000 | P10: 40000
A11: 9 | B11: Shinta | C11: 400000 | D11: iuran rutin | E11: iuran rutin | F11: iuran rutin | G11: 40000 | H11: 40000 | I11: 40000 | J11: 40000 | K11: 40000 | L11: 40000 | M11: 40000 | N11: 40000 | O11: 40000 | P11: 40000
A12: 10 | B12: Widi | C12: 400000 | D12: iuran rutin | E12: iuran rutin | F12: iuran rutin | G12: 40000 | H12: 40000 | I12: 40000 | J12: 40000 | K12: 40000 | L12: 40000 | M12: 40000 | N12: 40000 | O12: 40000 | P12: 40000
A13: 11 | B13: Tiwi | C13: 400000 | D13: iuran rutin | E13: iuran rutin | F13: iuran rutin | G13: 40000 | H13: 40000 | I13: 40000 | J13: 40000 | K13: 40000 | L13: 40000 | M13: 40000 | N13: 40000 | O13: 40000 | P13: 40000
A14: 12 | B14: Yuni | C14: 400000 | D14: iuran rutin | E14: iuran rutin | F14: iuran rutin | G14: 40000 | H14: 40000 | I14: 40000 | J14: 40000 | K14: 40000 | L14: 40000 | M14: 40000 | N14: 40000 | O14: 40000 | P14: 40000
A15: 13 | B15: Muna | C15: 400000 | D15: iuran rutin | E15: iuran rutin | F15: iuran rutin | G15: 40000 | H15: 40000 | I15: 40000 | J15: 40000 | K15: 40000 | L15: 40000 | M15: 40000 | N15: 40000 | O15: 40000 | P15: 40000
A16: 14 | B16: Siti | C16: 100000 | D16: 140000 | E16: 140000 | F16: 140000 | G16: 40000 | H16: 40000 | I16: 40000 | J16: 40000 | K16: 40000 | L16: 40000 | M16: 40000 | N16: 40000 | O16: 40000 | P16: 40000
A17: 15 | B17: Lis | C17: 100000 | D17: 140000 | E17: 140000 | F17: 140000 | G17: 40000 | H17: 40000 | I17: 40000 | J17: 40000 | K17: 40000 | L17: 40000 | M17: 40000 | N17: 40000 | O17: 40000 | P17: 40000
A18: 16 | B18: Esti | C18: 100000 | D18: 140000 | E18: 140000 | F18: 140000 | G18: 40000 | H18: 40000 | I18: 40000 | J18: 40000 | K18: 40000 | L18: 40000 | M18: 40000 | N18: 40000 | O18: 40000 | P18: 40000
A19: 17 | B19: Karlina | C19: 100000 | D19: 140000 | E19: 140000 | F19: 140000 | G19: 40000 | H19: 40000 | I19: 40000 | J19: 40000 | K19: 40000 | L19: 40000 | M19: 40000 | N19: 40000 | O19: 40000 | P19: 40000
A20: 18 | B20: Suryana | C20: 100000 | D20: 140000 | E20: 140000 | F20: 140000 | G20: 40000 | H20: 40000 | I20: 40000 | J20: 40000 | K20: 40000 | L20: 40000 | M20: 40000 | N20: 40000 | O20: 40000 | P20: 40000
A21: 19 | B21: Erlina | C21: 240000 | D21: 240000 | E21: 240000 | F21: 40000 | G21: 40000 | H21: 40000 | I21: 40000 | P21: 40000
A22: 20 | B22: Taufik | C22: 240000 | D22: 240000 | E22: 240000 | F22: 40000 | G22: 40000 | H22: 40000 | I22: 40000 | P22: 40000
A23: 23 | B23: Siti Mutofiah | C23: 240000 | D23: 240000 | E23: 40000 | F23: 40000 | G23: 40000 | H23: 40000 | I23: 40000 | P23: 40000
A24: 24 | B24: Iza | C24: 240000 | D24: 240000 | E24: 40000 | F24: 40000 | G24: 40000 | H24: 40000 | I24: 40000 | P24: 40000
A25: 25 | B25: Novi | C25: 100000 | D25: 140000 | E25: 140000 | F25: 140000 | G25: 40000 | H25: 40000 | I25: 40000 | J25: 40000 | K25: 40000 | L25: 40000 | M25: 40000 | N25: 40000 | O25: 40000 | P25: 40000

Sheet PINJAMAN
A1: No | B1: Nama | C1: Besar pinjaman | D1: 2024 | I1: 2025 | U1: 2026 | AG1: total Pinj | AH1: Total | AI1: Sisa | AJ1: Ket
D2: Agustus | E2: September | F2: Okt | G2: November | H2: Desember | I2: Januari 2025 | J2: Februari | K2: Maret | L2: April | M2: Mei | N2: Juni | O2: Juli | P2: Agst | Q2: Sept | R2: Okt | S2: Nov | T2: Desember | U2: Jan | V2: Feb | W2: Maret | X2: April | Y2: Mei | Z2: Juni | AA2: Juli | AB2: Agustus | AC2: Sept | AD2: Okt | AE2: Nov | AF2: Des | AH2: Angsuran
A3: 1 | B3: Syukria | C3: 6650000 | D3: 600000 | E3: 600000 | F3: 0 | H3: 600000 | I3: 600000 | J3: 600000 | K3: 600000 | L3: 600000 | M3: 600000 | N3: 600000 | O3: 600000 | P3: 600000 | Q3: 600000 | R3: 600000 | S3: 600000 | T3: 600000 | U3: 600000 | V3: 600000 | W3: 600000 | X3: 600000 | Y3: 600000 | Z3: 600000 | AA3: 200000 | AG3: =SUM(AH3:AI3) -> 12800000 | AH3: =SUM(D3:W3) -> 10800000 | AI3: =SUM(X3:AF3) -> 2000000
A4: 2 | B4: Aris | C4: 12000000 | I4: 600000 | J4: 400000 | K4: 500000 | L4: 500000 | M4: 500000 | N4: 500000 | O4: 500000 | P4: 500000 | Q4: 500000 | R4: 500000 | S4: 500000 | T4: 500000 | U4: 500000 | V4: 500000 | W4: 500000 | X4: 500000 | Y4: 500000 | Z4: 500000 | AA4: 500000 | AB4: 500000 | AC4: 500000 | AD4: 500000 | AE4: 500000 | AF4: 500000 | AG4: =SUM(AH4:AI4) -> 12000000 | AH4: =SUM(D4:W4) -> 7500000 | AI4: =SUM(X4:AF4) -> 4500000
A5: 4 | B5: Sandi | C5: 1000000 | U5: 200000 | V5: 200000 | W5: 200000 | X5: 200000 | Y5: 200000 | AG5: =SUM(AH5:AI5) -> 1000000 | AH5: =SUM(D5:W5) -> 600000 | AI5: =SUM(X5:AF5) -> 400000
A6: 5 | B6: Yusuf | C6: 1500000 | V6: 187500 | W6: 187500 | X6: 187500 | Y6: 187500 | Z6: 187500 | AA6: 187500 | AB6: 187500 | AC6: 187500 | AG6: =SUM(AH6:AI6) -> 1500000 | AH6: =SUM(D6:W6) -> 375000 | AI6: =SUM(X6:AF6) -> 1125000
A7: 6 | B7: Fia | C7: 3500000 | U7: 2500000 | V7: 875000 | W7: 125000 | AG7: =SUM(AH7:AI7) -> 3500000 | AH7: =SUM(D7:W7) -> 3500000 | AI7: =SUM(X7:AF7) -> 0
A8: 7 | B8: Andi | C8: 2000000 | W8: 350000 | X8: 350000 | Y8: 350000 | Z8: 350000 | AA8: 300000 | AB8: 300000 | AG8: =SUM(W8:AB8) -> 2000000 | AH8: =SUM(D8:W8) -> 350000 | AI8: =SUM(X8:AF8) -> 1650000
A9: 8 | B9: Listia | C9: 3000000 | X9: 1000000 | Y9: 1000000 | Z9: 1000000 | AG9: =SUM(W9:Y9) -> 2000000 | AH9: =SUM(D9:W9) -> 0 | AI9: =SUM(X9:AF9) -> 3000000
A10: 9 | B10: Novita P.F. | C10: 5000000 | X10: 1000000 | Y10: 1000000 | Z10: 1000000 | AA10: 1000000 | AB10: 1000000 | AG10: =SUM(X10:AB10) -> 5000000 | AH10: =SUM(D10:W10) -> 0 | AI10: =SUM(X10:AF10) -> 5000000
B11: Note
B12: Rincian Pembiayaan Neisha
A13: TK | B13: 1. SPP : 12 x 300.000 | C13: =12*300000 -> 3600000
B14: 2. Biaya Masuk TK | C14: 3350000
C15: =SUM(C13:C14) -> 6950000 | D15: TK LUNAS
A17: SD | B17: 1. Spp
B18: 2. Biaya masuk
B19: sisa hutang per januari

Sheet PER UNIT
B1: DATA ABSENSI SDM YAYASAN BINA INSAN MULIA BATAM PER TMT
B3: 1 | C3: 2 | D3: 3 | E3: 4 | F3: 5 | G3: 6 | I3: 8 | J3: 9 | K3: 10 | L3: 11 | M3: 12 | N3: 13 | O3: 14 | P3: 15 | Q3: 16 | R3: 17 | S3: 18 | T3: 19 | U3: 20 | V3: 21 | W3: 22 | X3: 23 | Y3: 24 | Z3: 25 | AA3: 26 | AB3: 27 | AC3: 28 | AD3: 29 | AE3: 30 | AF3: 31 | AG3: 32 | AH3: 33 | AI3: 34 | AJ3: 35 | AK3: 36 | AL3: 37 | AM3: 38 | AN3: 39 | AO3: 40 | AP3: 41 | AQ3: 42 | AR3: 43 | AS3: 44 | AT3: 45 | AW3: 46 | AX3: 47 | AY3: 48 | AZ3: 49 | BA3: 50 | BB3: 51 | BC3: 52 | BD3: 53 | BE3: 54 | BF3: 55 | BG3: 56 | BH3: 57 | BI3: 58 | BJ3: 59 | BK3: 60 | BL3: 61 | BM3: 62 | BN3: 63 | BO3: 64 | BP3: 65 | BQ3: 66 | BR3: 67 | BS3: 68 | BT3: 69
A4: N0 | B4: KODESLIP | C4: NAMA | D4: NRK | E4: UNIT | F4: TTL | G4: BULAN | H4: JOIN DATE | I4: MASA KERJA | J4: STATUS KARY. | K4: STATUS PERNIKAHAN | L4: PENDIDIKAN | M4: GRADE | N4: GRADE KHUSUS | O4: JABATAN | P4: KODE JABATAN | Q4: JML HARI KERJA | R4: ON TIME | S4: TELAT | T4: SAKIT | U4: IZIN | V4: TANPA KET. | W4: ESKUL PRAMUKA | X4: INST. RENANG | Y4: ASST. RENANG | Z4: TUGAS DI HR. KERJA | AA4: TGS. DI HR. LIBUR | AB4: ASST. RENANG | AC4: TAMBAH JAM | AD4: DAYCARE BAYI | AE4: DAY CARE ANAK PG-TK | AF4: MASUK MALAM/MAKAN | AG4: MUSRIF/AH | AH4: FUTSAL | AI4: EKSKUL WAJIB | AJ4: EKSKUL PILIHAN | AK4: GAJI POKOK | AL4: TUNJ. FUNGSIONAL | AM4: TUNJ. KEHADIRAN | AN4: TUNJ. RUMAH | AO4: TUNJ. MASA KERJA | AP4: TUNJ. BPJS KESEHATAN | AQ4: TUNJ. ESKUL | AR4: TUNJ. LEMBUR | AS4: TUNJ. MAKAN | AT4: TUNJ. SUKA/DUKA | AU4: BEASISWA TK | AV4: BEASISWA SD | AW4: BEASISWA SMP | AX4: TUNJ. Khusus | AY4: Ket Tj Khusus | AZ4: SUBSIDI PENITIPAN | BA4: SUBSIDI TPQ | BB4: Tunj Insentif PEMKO | BC4: BPJS KETENA KERJAAN | BD4: GAJI SBLM POTONGAN | BE4: POTONGAN ABSEN | BF4: POTONGAN TELAT | BG4: POTONGAN DAY CARE | BH4: POTONGAN BPJS KESEHATAN | BI4: POTONGAN PINJAMAN | BJ4: POTONGAN ZISWAF | BK4: POT BPJS TENAGA KERJA | BL4: POT. BIAYA PENDIDIKAN | BM4: POT. PEMKO | BN4: IURAN BPJS YYS | BO4: NIHIL | BP4: TOTAL POTONGAN | BQ4: KOREKSI GAJI | BR4: KETERANGAN KOREKSI | BS4: GAJI BERSIH | BT4: No.Rek Bank
S5: 7500 | T5: 25000 | U5: 40000 | V5: 60000 | W5: 25000 | X5: 75000 | Y5: 25000 | Z5: 30000 | AA5: 50000 | AD5: 250000 | AE5: 175000 | AF5: 20000 | AG5: 30000 | AH5: 100000 | AI5: 50000 | AJ5: 30000 | AT5: 1000000 | AU5: 685000 | AV5: 950000 | AW5: 1500000 | BC5: 84800 | BK5: 40000
A7: 1 | B7: SLP001 | C7: AA1 | D7: 210.005 | E7: RA IT | F7: Madiun, 21 April | G7: Februari | H7: 20 Juli 2010 | I7: 15 | J7: TETAP | K7: BM | L7: SMA | M7: 1A | N7: IA5 | O7: Admin RA | P7: ADR | Q7: 19 | R7: 19 | AA7: 1 | AK7: =VLOOKUP(N7,Gapok!$B$5:$I$94,6,0) -> 900000 | AL7: =VLOOKUP(P7,'TJ. FUNGSIONAL'!$B$4:$F$34,5,0) -> 400000 | AM7: =IF(R7+S7>=Q7,VLOOKUP(N7,[1]Gapok!$B$5:$I$94,8,0),VLOOKUP('[1]PER UNIT'!N7,[1]Gapok!$B$5:$I$94,7,0)*('[1]PER UNIT'!R7+'[1]PER UNIT'!S7)) -> 375000 | AN7: =VLOOKUP(P7,'TJ. FUNGSIONAL'!$B$4:$E$34,4,0) -> 300000 | AO7: =50000*I7 -> 750000 | AP7: 35000 | AQ7: =(W7*25000)+X7*75000+Y7*25000+AH7*100000+AI7*50000+AJ7*30000 -> 0 | AR7: =Z7*30000+AA7*50000 -> 50000 | AS7: =25000*AF7 -> 0 | BB7: 985000 | BC7: 84800 | BD7: =SUM(AK7:BC7) -> 3879800 | BE7: =T7*25000+U7*40000+V7*60000 -> 0 | BF7: =7500*S7 -> 0 | BG7: =250000*AD7+175000*AE7 -> 0 | BH7: 0 | BI7: 0 | BK7: 40000 | BL7: =SUM(AU7:AW7) -> 0 | BM7: 985000 | BN7: 84800 | BP7: =SUM(BE7:BO7) -> 1109800 | BS7: =BD7-BP7+BQ7 -> 2770000 | BT7: 7023047998
A8: 2 | B8: SLP002 | C8: AA2 | D8: 210.010 | E8: RA IT | F8: Sleman, 19 Maret 1980 | G8: Februari | H8: 20 Juli 2010 | I8: 15 | J8: TETAP | K8: M3 | L8: S1 | M8: IC | N8: IIA1 | O8: =VLOOKUP(P8,'TJ. FUNGSIONAL'!$B$4:$C$34,2,0) -> Kepala RA | P8: KAR | Q8: 19 | R8: 19 | AA8: 1 | AK8: =VLOOKUP(N8,Gapok!$B$5:$I$94,6,0) -> 1650000 | AL8: =VLOOKUP(P8,'TJ. FUNGSIONAL'!$B$4:$F$34,5,0) -> 1500000 | AM8: =IF(R8+S8>=Q8,VLOOKUP(N8,[1]Gapok!$B$5:$I$94,8,0),VLOOKUP('[1]PER UNIT'!N8,[1]Gapok!$B$5:$I$94,7,0)*('[1]PER UNIT'!R8+'[1]PER UNIT'!S8)) -> 450000 | AN8: =VLOOKUP(P8,'TJ. FUNGSIONAL'!$B$4:$E$34,4,0) -> 500000 | AO8: =50000*I8 -> 750000 | AP8: 140000 | AQ8: =(W8*25000)+X8*75000+Y8*25000+AH8*100000+AI8*50000+AJ8*30000 -> 0 | AR8: =Z8*30000+AA8*50000 -> 50000 | AS8: =25000*AF8 -> 0 | AV8: =3*950000 -> 2850000 | BB8: 985000 | BC8: 84800 | BD8: =SUM(AK8:BC8) -> 8959800 | BE8: =T8*25000+U8*40000+V8*60000 -> 0 | BF8: =7500*S8 -> 0 | BG8: =250000*AD8+175000*AE8 -> 0 | BH8: =35000*6 -> 210000 | BI8: 0 | BK8: 40000 | BL8: =SUM(AU8:AW8) -> 2850000 | BM8: 985000 | BN8: 84800 | BP8: =SUM(BE8:BO8) -> 4169800 | BS8: =BD8-BP8+BQ8 -> 4790000 | BT8: 7106887416
A9: 3 | B9: SLP003 | C9: AA3 | D9: 210.013 | E9: RA IT | F9: Purba Bangun, 01 April 1971 | G9: Februari | H9: 20 Juli 2010 | I9: 15 | J9: TETAP | K9: M5 | L9: SMA | M9: IA | N9: IA5 | O9: =VLOOKUP(P9,'TJ. FUNGSIONAL'!$B$4:$C$34,2,0) -> Petugas Kebersihan | P9: PKR | Q9: 19 | R9: 13 | U9: 6 | AA9: 1 | AK9: =VLOOKUP(N9,Gapok!$B$5:$I$94,6,0) -> 900000 | AL9: =VLOOKUP(P9,'TJ. FUNGSIONAL'!$B$4:$F$34,5,0) -> 400000 | AM9: =IF(R9+S9>=Q9,VLOOKUP(N9,[1]Gapok!$B$5:$I$94,8,0),VLOOKUP('[1]PER UNIT'!N9,[1]Gapok!$B$5:$I$94,7,0)*('[1]PER UNIT'!R9+'[1]PER UNIT'!S9)) -> 270000 | AN9: =VLOOKUP(P9,'TJ. FUNGSIONAL'!$B$4:$E$34,4,0) -> 300000 | AO9: =50000*I9 -> 750000 | AP9: 35000 | AQ9: =(W9*25000)+X9*75000+Y9*25000+AH9*100000+AI9*50000+AJ9*30000 -> 0 | AR9: =Z9*30000+AA9*50000 -> 50000 | AS9: =25000*AF9 -> 0 | BB9: 985000 | BD9: =SUM(AK9:BC9) -> 3690000 | BE9: =T9*25000+U9*40000+V9*60000 -> 240000 | BF9: =7500*S9 -> 0 | BG9: =250000*AD9+175000*AE9 -> 0 | BH9: 0 | BI9: 0 | BL9: =SUM(AU9:AW9) -> 0 | BM9: 985000 | BP9: =SUM(BE9:BO9) -> 1225000 | BS9: =BD9-BP9+BQ9 -> 2465000 | BT9: 7106887467
A10: 4 | B10: SLP004 | C10: AA4 | D10: 210.017 | E10: RA IT | F10: Nganjuk 19-12-1986 | G10: Februari | H10: 1 Desember 2010 | I10: 13 | J10: TETAP | K10: M2 | L10: S1 | M10: IC | N10: IC5 | O10: =VLOOKUP(P10,'TJ. FUNGSIONAL'!$B$4:$C$34,2,0) -> Wakil Kepala RA | P10: WAR | Q10: 19 | R10: 19 | AA10: 1 | AE10: 1 | AK10: =VLOOKUP(N10,Gapok!$B$5:$I$94,6,0) -> 1450000 | AL10: =VLOOKUP(P10,'TJ. FUNGSIONAL'!$B$4:$F$34,5,0) -> 1200000 | AM10: =IF(R10+S10>=Q10,VLOOKUP(N10,[1]Gapok!$B$5:$I$94,8,0),VLOOKUP('[1]PER UNIT'!N10,[1]Gapok!$B$5:$I$94,7,0)*('[1]PER UNIT'!R10+'[1]PER UNIT'!S10)) -> 425000 | AN10: =VLOOKUP(P10,'TJ. FUNGSIONAL'!$B$4:$E$34,4,0) -> 400000 | AO10: =50000*I10 -> 650000 | AP10: 35000 | AQ10: =(W10*25000)+X10*75000+Y10*25000+AH10*100000+AI10*50000+AJ10*30000 -> 0 | AR10: =Z10*30000+AA10*50000 -> 50000 | AS10: =25000*AF10 -> 0 | AW10: 1500000 | BB10: 985000 | BC10: 84800 | BD10: =SUM(AK10:BC10) -> 6779800 | BE10: =T10*25000+U10*40000+V10*60000 -> 0 | BF10: =7500*S10 -> 0 | BG10: =250000*AD10+175000*AE10 -> 175000 | BH10: 35000 | BI10: 125000 | BK10: 40000 | BL10: =SUM(AU10:AW10) -> 1500000 | BM10: 985000 | BN10: 84800 | BP10: =SUM(BE10:BO10) -> 2944800 | BS10: =BD10-BP10+BQ10 -> 3835000 | BT10: 7106921487
A11: 5 | B11: SLP005 | C11: AA5 | D11: 218.119 | E11: RA IT | F11: Sidoarjo, 08 September 2000 | G11: Februari | H11: 20 Agustus 2018 | I11: 6 | J11: TETAP | K11: BM | L11: S1 | M11: 1C | N11: IC1 | O11: =VLOOKUP(P11,'TJ. FUNGSIONAL'!$B$4:$C$34,2,0) -> Wali Kelas RA | P11: WKR | Q11: 19 | R11: 11 | S11: 8 | W11: 6 | AA11: 1 | AK11: =VLOOKUP(N11,Gapok!$B$5:$I$94,2,0) -> 1020000 | AL11: =VLOOKUP(P11,'TJ. FUNGSIONAL'!$B$4:$F$34,5,0) -> 700000 | AM11: =IF(R11+S11>=Q11,VLOOKUP(N11,[1]Gapok!$B$5:$I$94,8,0),VLOOKUP('[1]PER UNIT'!N11,[1]Gapok!$B$5:$I$94,7,0)*('[1]PER UNIT'!R11+'[1]PER UNIT'!S11)) -> 425000 | AN11: =VLOOKUP(P11,'TJ. FUNGSIONAL'!$B$4:$E$34,4,0) -> 300000 | AO11: =50000*I11 -> 300000 | AP11: 35000 | AQ11: =(W11*25000)+X11*75000+Y11*25000+AH11*100000+AI11*50000+AJ11*30000 -> 150000 | AR11: =Z11*30000+AA11*50000 -> 50000 | AS11: =25000*AF11 -> 0 | BB11: 985000 | BC11: 84800 | BD11: =SUM(AK11:BC11) -> 4049800 | BE11: =T11*25000+U11*40000+V11*60000 -> 0 | BF11: =7500*S11 -> 60000 | BG11: =250000*AD11+175000*AE11 -> 0 | BH11: 35000 | BI11: 0 | BK11: 40000 | BL11: =SUM(AU11:AW11) -> 0 | BM11: 985000 | BN11: 84800 | BP11: =SUM(BE11:BO11) -> 1204800 | BS11: =BD11-BP11+BQ11 -> 2845000 | BT11: 7123023287
A12: 6 | B12: SLP006 | C12: AA6 | D12: 224.244 | E12: RA IT | F12: Bandung, 27 Juli 1974 | G12: Februari | H12: 12 Oktober 2024 | I12: 0 | J12: KONTRAK | K12: M3 | L12: SMA | M12: IA | N12: IA1 | O12: Karyawan Penitipan | P12: KYP | Q12: 19 | R12: 19 | AA12: 1 | AK12: =VLOOKUP(N12,Gapok!$B$5:$I$94,2,0) -> 800000 | AL12: =VLOOKUP(P12,'TJ. FUNGSIONAL'!$B$4:$F$34,5,0) -> 400000 | AM12: =IF(R12+S12>=Q12,(VLOOKUP(N12,[1]Gapok!$B$5:$I$94,5,0)),((VLOOKUP('[1]PER UNIT'!N12,[1]Gapok!$B$5:$I$94,4,0)*('[1]PER UNIT'!R12+'[1]PER UNIT'!S12)))) -> 375000 | AN12: =VLOOKUP(P12,'TJ. FUNGSIONAL'!$B$4:$E$34,4,0) -> 300000 | AO12: =50000*I12 -> 0 | AP12: 35000 | AQ12: =(W12*25000)+X12*75000+Y12*25000+AH12*100000+AI12*50000+AJ12*30000 -> 0 | AR12: =Z12*30000+AA12*50000 -> 50000 | AS12: =25000*AF12 -> 0 | BD12: =SUM(AK12:BC12) -> 1960000 | BE12: =T12*25000+U12*40000+V12*60000 -> 0 | BF12: =7500*S12 -> 0 | BG12: =250000*AD12+175000*AE12 -> 0 | BH12: 0 | BI12: 0 | BL12: =SUM(AU12:AW12) -> 0 | BP12: =SUM(BE12:BO12) -> 0 | BS12: =BD12-BP12+BQ12 -> 1960000 | BT12: 7301903469
A13: 7 | B13: SLP007 | C13: AA7 | D13: 224.239 | E13: RA IT | F13: Selat Panjang, 2 Juli 1997 | G13: Februari | H13: 13 Juli 2024 | I13: 1 | J13: KONTRAK | K13: M1 | L13: SMA | M13: 1C | N13: IC1 | O13: =VLOOKUP(P13,'TJ. FUNGSIONAL'!$B$4:$C$34,2,0) -> Guru Kelas RA | P13: GKR | AK13: =VLOOKUP(N13,Gapok!$B$5:$I$94,2,0) -> 1020000 | AL13: =VLOOKUP(P13,'TJ. FUNGSIONAL'!$B$4:$F$34,5,0) -> 500000 | AN13: =VLOOKUP(P13,'TJ. FUNGSIONAL'!$B$4:$E$34,4,0) -> 300000 | AO13: =50000*I13 -> 50000 | AP13: 35000 | AQ13: =(W13*25000)+X13*75000+Y13*25000+AH13*100000+AI13*50000+AJ13*30000 -> 0 | AR13: =Z13*30000+AA13*50000 -> 0 | AS13: =25000*AF13 -> 0 | AT13: 1000000 | BD13: =SUM(AK13:BC13) -> 2905000 | BE13: =T13*25000+U13*40000+V13*60000 -> 0 | BF13: =7500*S13 -> 0 | BG13: =250000*AD13+175000*AE13 -> 0 | BH13: 0 | BI13: 0 | BL13: =SUM(AU13:AW13) -> 0 | BP13: =SUM(BE13:BO13) -> 0 | BS13: =BD13-BP13+BQ13 -> 2905000 | BT13: 7149700425 | BU13: CUTI MELAHIRKAN
A14: 8 | B14: SLP008 | C14: AA8 | D14: 225.254 | E14: RA IT | F14: Purwakarta, 29 Mei 2001 | G14: Februari | H14: 10 Juli 2025 | I14: 0 | J14: KONTRAK | K14: M0 | L14: SMA | M14: IA | N14: IA3 | O14: =VLOOKUP(P14,'TJ. FUNGSIONAL'!$B$4:$C$34,2,0) -> Guru Kelas RA | P14: GKR | Q14: 19 | R14: 17 | S14: 2 | W14: 6 | AA14: 1 | AK14: =VLOOKUP(N14,Gapok!$B$5:$I$94,2,0) -> 840000 | AL14: =VLOOKUP(P14,'TJ. FUNGSIONAL'!$B$4:$F$34,5,0) -> 500000 | AM14: =IF(R14+S14>=Q14,(VLOOKUP(N14,[1]Gapok!$B$5:$I$94,5,0)),((VLOOKUP('[1]PER UNIT'!N14,[1]Gapok!$B$5:$I$94,4,0)*('[1]PER UNIT'!R14+'[1]PER UNIT'!S14)))) -> 375000 | AN14: =VLOOKUP(P14,'TJ. FUNGSIONAL'!$B$4:$E$34,4,0) -> 300000 | AO14: =50000*I14 -> 0 | AP14: 35000 | AQ14: =(W14*25000)+X14*75000+Y14*25000+AH14*100000+AI14*50000+AJ14*30000 -> 150000 | AR14: =Z14*30000+AA14*50000 -> 50000 | AS14: =25000*AF14 -> 0 | BD14: =SUM(AK14:BC14) -> 2250000 | BE14: =T14*25000+U14*40000+V14*60000 -> 0 | BF14: =7500*S14 -> 15000 | BG14: =250000*AD14+175000*AE14 -> 0 | BH14: 0 | BI14: 0 | BL14: =SUM(AU14:AW14) -> 0 | BP14: =SUM(BE14:BO14) -> 15000 | BS14: =BD14-BP14+BQ14 -> 2235000 | BT14: 7328941397
A15: 9 | B15: SLP009 | C15: AA9 | D15: 225.255 | E15: RA IT | F15: Tegal 27 Februari 2005 | G15: Februari | H15: 10 Juli 2025 | I15: 0 | J15: KONTRAK | K15: BM | L15: SMA | M15: IA | N15: IA3 | O15: =VLOOKUP(P15,'TJ. FUNGSIONAL'!$B$4:$C$34,2,0) -> Guru Kelas RA | P15: GKR | Q15: 19 | R15: 19 | AA15: 1 | AK15: =VLOOKUP(N15,Gapok!$B$5:$I$94,2,0) -> 840000 | AL15: =VLOOKUP(P15,'TJ. FUNGSIONAL'!$B$4:$F$34,5,0) -> 500000 | AM15: =IF(R15+S15>=Q15,(VLOOKUP(N15,[1]Gapok!$B$5:$I$94,5,0)),((VLOOKUP('[1]PER UNIT'!N15,[1]Gapok!$B$5:$I$94,4,0)*('[1]PER UNIT'!R15+'[1]PER UNIT'!S15)))) -> 375000 | AN15: =VLOOKUP(P15,'TJ. FUNGSIONAL'!$B$4:$E$34,4,0) -> 300000 | AO15: =50000*I15 -> 0 | AP15: 35000 | AQ15: =(W15*25000)+X15*75000+Y15*25000+AH15*100000+AI15*50000+AJ15*30000 -> 0 | AR15: =Z15*30000+AA15*50000 -> 50000 | AS15: =25000*AF15 -> 0 | BD15: =SUM(AK15:BC15) -> 2100000 | BE15: =T15*25000+U15*40000+V15*60000 -> 0 | BF15: =7500*S15 -> 0 | BG15: =250000*AD15+175000*AE15 -> 0 | BH15: 0 | BI15: 0 | BL15: =SUM(AU15:AW15) -> 0 | BP15: =SUM(BE15:BO15) -> 0 | BS15: =BD15-BP15+BQ15 -> 2100000 | BT15: 7328940625
A16: 10 | B16: SLP010 | C16: AA10 | D16: 225.258 | E16: RA IT | F16: Masjid Lama, 09 Agustus 1998 | G16: Februari | H16: 31 Juli 2025 | I16: 0 | J16: KONTRAK | K16: BM | L16: S1 | M16: 1C | N16: IC1 | O16: Guru Kelas RA | P16: GKR | Q16: 19 | R16: 19 | AA16: 1 | AK16: =VLOOKUP(N16,Gapok!$B$5:$I$94,2,0) -> 1020000 | AL16: =VLOOKUP(P16,'TJ. FUNGSIONAL'!$B$4:$F$34,5,0) -> 500000 | AM16: =IF(R16+S16>=Q16,(VLOOKUP(N16,[1]Gapok!$B$5:$I$94,5,0)),((VLOOKUP('[1]PER UNIT'!N16,[1]Gapok!$B$5:$I$94,4,0)*('[1]PER UNIT'!R16+'[1]PER UNIT'!S16)))) -> 375000 | AN16: =VLOOKUP(P16,'TJ. FUNGSIONAL'!$B$4:$E$34,4,0) -> 300000 | AO16: =50000*I16 -> 0 | AP16: 35000 | AR16: =Z16*30000+AA16*50000 -> 50000 | AS16: =25000*AF16 -> 0 | BD16: =SUM(AK16:BC16) -> 2280000 | BE16: =T16*25000+U16*40000+V16*60000 -> 0 | BF16: =7500*S16 -> 0 | BG16: =250000*AD16+175000*AE16 -> 0 | BH16: 0 | BI16: 0 | BL16: =SUM(AU16:AW16) -> 0 | BP16: =SUM(BE16:BO16) -> 0 | BS16: =BD16-BP16+BQ16 -> 2280000 | BT16: 7320036482
A17: 11 | B17: SLP011 | C17: AA11 | D17: 219.126 | E17: YAYASAN | F17: Banyumas, 7 Maret 1979 | G17: Februari | H17: 15 Mei 2019 | I17: 6 | J17: TETAP | K17: M5 | L17: S1 | M17: IIA | N17: IIA1 | O17: Kepala Divisi | P17: KDV | Q17: 18 | R17: 17 | S17: 1 | AA17: 1 | AK17: =VLOOKUP(N17,Gapok!$B$5:$I$94,6,0) -> 1650000 | AL17: =VLOOKUP(P17,'TJ. FUNGSIONAL'!$B$4:$F$34,3,0) -> 1850000 | AM17: =IF(R21+S17>=Q17,VLOOKUP(N17,Gapok!$B$5:$I$94,8,0),VLOOKUP('PER UNIT'!N17,Gapok!$B$5:$I$94,7,0)*('PER UNIT'!R21+'PER UNIT'!S17)) -> 450000 | AN17: =VLOOKUP(P17,'TJ. FUNGSIONAL'!$B$4:$E$34,4,0) -> 750000 | AO17: =50000*I17 -> 300000 | AP17: 140000 | AQ17: =(W17*25000)+X17*75000+Y17*25000+AH17*100000+AI17*50000+AJ17*30000 -> 0 | AR17: =Z17*30000+AA17*50000 -> 50000 | AS17: =25000*AF17 -> 0 | AV17: =950000+1000000 -> 1950000 | BC17: 84800 | BD17: =SUM(AK17:BC17) -> 7224800 | BE17: =T17*25000+U17*40000+V17*60000 -> 0 | BF17: =7500*S17 -> 7500 | BG17: =250000*AD17+175000*AE17 -> 0 | BH17: 140000 | BI17: 0 | BK17: 40000 | BL17: =SUM(AU17:AW17) -> 1950000 | BN17: 84800 | BP17: =SUM(BE17:BO17) -> 2222300 | BS17: =BD17-BP17+BQ17 -> 5002500 | BT17: 7023047947
A18: 12 | B18: SLP012 | C18: AA12 | D18: 210.008 | E18: SDIT | F18: Jember, 12 Desember 1985 | G18: Februari | H18: 7 Juli 2010 | I18: 15 | J18: TETAP | K18: M3 | L18: S1 | M18: IIC | N18: IIIA1 | O18: =VLOOKUP(P18,'TJ. FUNGSIONAL'!$B$4:$C$34,2,0) -> Kepala SD | P18: KAD | Q18: 18 | R18: 18 | W18: 2 | AE18: 1 | AK18: =VLOOKUP(N18,Gapok!$B$5:$I$94,6,0) -> 2500000 | AL18: =VLOOKUP(P18,'TJ. FUNGSIONAL'!$B$4:$F$34,5,0) -> 2200000 | AM18: =IF(R22+S18>=Q18,VLOOKUP(N18,Gapok!$B$5:$I$94,8,0),VLOOKUP('PER UNIT'!N18,Gapok!$B$5:$I$94,7,0)*('PER UNIT'!R22+'PER UNIT'!S18)) -> 525000 | AN18: =VLOOKUP(P18,'TJ. FUNGSIONAL'!$B$4:$E$34,4,0) -> 750000 | AO18: =50000*I18 -> 750000 | AP18: 35000 | AQ18: =(W18*25000)+X18*75000+Y18*25000+AH18*100000+AI18*50000+AJ18*30000 -> 50000 | AR18: =Z18*30000+AA18*50000 -> 0 | AS18: =25000*AF18 -> 0 | AU18: 685000 | AV18: 2000000 | BB18: 975000 | BC18: 84800 | BD18: =SUM(AK18:BC18) -> 10554800 | BE18: =T18*25000+U18*40000+V18*60000 -> 0 | BF18: =7500*S18 -> 0 | BG18: =250000*AD18+175000*AE18 -> 175000 | BH18: 0 | BI18: 0 | BK18: 40000 | BL18: =SUM(AU18:AW18) -> 2685000 | BM18: 975000 | BN18: 84800 | BP18: =SUM(BE18:BO18) -> 3959800 | BS18: =BD18-BP18+BQ18 -> 6595000 | BT18: 7030278784
A19: 13 | B19: SLP013 | C19: AA13 | D19: 211.020 | E19: SDIT | F19: Lamongan, 06 Juni 1980 | G19: Februari | H19: 22 Juni 2011 | I19: 14 | J19: TETAP | K19: M5 | L19: S1 | M19: IB | N19: IC1 | O19: =VLOOKUP(P19,'TJ. FUNGSIONAL'!$B$4:$C$34,2,0) -> Wakil Kepala SD | P19: WAD | Q19: 18 | R19: 18 | W19: 2 | AK19: =VLOOKUP(N19,Gapok!$B$5:$I$94,6,0) -> 1350000 | AL19: =VLOOKUP(P19,'TJ. FUNGSIONAL'!$B$4:$F$34,5,0) -> 1700000 | AM19: =IF(R21+S19>=Q19,VLOOKUP(N19,Gapok!$B$5:$I$94,8,0),VLOOKUP('PER UNIT'!N19,Gapok!$B$5:$I$94,7,0)*('PER UNIT'!R21+'PER UNIT'!S19)) -> 425000 | AN19: =VLOOKUP(P19,'TJ. FUNGSIONAL'!$B$4:$E$34,4,0) -> 500000 | AO19: =50000*I19 -> 700000 | AP19: 35000 | AQ19: =(W19*25000)+X19*75000+Y19*25000+AH19*100000+AI19*50000+AJ19*30000 -> 50000 | AR19: =Z19*30000+AA19*50000 -> 0 | AS19: =25000*AF19 -> 0 | AV19: 1000000 | AW19: 1500000 | BB19: 975000 | BC19: 84800 | BD19: =SUM(AK19:BC19) -> 8319800 | BE19: =T19*25000+U19*40000+V19*60000 -> 0 | BF19: =7500*S19 -> 0 | BG19: =250000*AD19+175000*AE19 -> 0 | BH19: 0 | BI19: 0 | BK19: 40000 | BL19: =SUM(AU19:AW19) -> 2500000 | BM19: 975000 | BN19: 84800 | BP19: =SUM(BE19:BO19) -> 3599800 | BS19: =BD19-BP19+BQ19 -> 4720000 | BT19: 7107158353
A20: 14 | B20: SLP014 | C20: AA14 | D20: 212.030 | E20: SDIT | F20: Karanganyar, 06 Februari 1983 | G20: Februari | H20: 4 Juli 2012 | I20: 13 | J20: TETAP | K20: M1 | L20: S1 | M20: IIB | N20: IIB7 | O20: =VLOOKUP(P20,'TJ. FUNGSIONAL'!$B$4:$C$34,2,0) -> Kepala Divisi | P20: KDV | Q20: 18 | R20: 16 | S20: 2 | W20: 2 | AK20: =VLOOKUP(N20,Gapok!$B$5:$I$94,6,0) -> 2075000 | AL20: =VLOOKUP(P20,'TJ. FUNGSIONAL'!$B$4:$F$34,5,0) -> 2200000 | AM20: =IF(R20+S20>=Q20,VLOOKUP(N20,Gapok!$B$5:$I$94,8,0),VLOOKUP('PER UNIT'!N20,Gapok!$B$5:$I$94,7,0)*('PER UNIT'!R20+'PER UNIT'!S20)) -> 475000 | AN20: =VLOOKUP(P20,'TJ. FUNGSIONAL'!$B$4:$E$34,4,0) -> 750000 | AO20: =50000*I20 -> 650000 | AP20: 35000 | AQ20: =(W20*25000)+X20*75000+Y20*25000+AH20*100000+AI20*50000+AJ20*30000 -> 50000 | AR20: =Z20*30000+AA20*50000 -> 0 | AS20: =25000*AF20 -> 0 | AV20: 1000000 | BB20: 975000 | BC20: 84800 | BD20: =SUM(AK20:BC20) -> 8294800 | BE20: =T20*25000+U20*40000+V20*60000 -> 0 | BF20: =7500*S20 -> 15000 | BG20: =250000*AD20+175000*AE20 -> 0 | BH20: 35000 | BI20: 0 | BK20: 40000 | BL20: =SUM(AU20:AW20) -> 1000000 | BM20: 975000 | BN20: 84800 | BP20: =SUM(BE20:BO20) -> 2149800 | BS20: =BD20-BP20+BQ20 -> 6145000 | BT20: 7040707349
A21: 15 | B21: SLP015 | C21: AA15 | D21: 214.064 | E21: SDIT | F21: Desa Bantan, 21-01-1984 | G21: Februari | H21: 1 Desember 2014 | I21: 10 | J21: TETAP | K21: M3 | L21: SMA | M21: IA | N21: IA5 | O21: =VLOOKUP(P21,'TJ. FUNGSIONAL'!$B$4:$C$34,2,0) -> Petugas Dapur | P21: PDY | Q21: 18 | R21: 18 | Z21: 14 | AA21: 1 | AE21: 1 | AK21: =VLOOKUP(N21,Gapok!$B$5:$I$94,6,0) -> 900000 | AL21: 990000 | AM21: =IF(R21+S21>=Q21,VLOOKUP(N21,Gapok!$B$5:$I$94,8,0),VLOOKUP('PER UNIT'!N21,Gapok!$B$5:$I$94,7,0)*('PER UNIT'!R21+'PER UNIT'!S21)) -> 375000 | AN21: =VLOOKUP(P21,'TJ. FUNGSIONAL'!$B$4:$E$34,4,0) -> 300000 | AO21: =50000*I21 -> 500000 | AP21: 35000 | AQ21: =(W21*25000)+X21*75000+Y21*25000+AH21*100000+AI21*50000+AJ21*30000 -> 0 | AR21: =Z21*30000+AA21*50000 -> 470000 | AS21: =25000*AF21 -> 0 | AU21: 685000 | AV21: 1000000 | AW21: 1500000 | BC21: 84800 | BD21: =SUM(AK21:BC21) -> 6839800 | BE21: =T21*25000+U21*40000+V21*60000 -> 0 | BF21: =7500*S21 -> 0 | BG21: =250000*AD21+175000*AE21 -> 175000 | BH21: 35000 | BI21: 0 | BK21: 40000 | BL21: =SUM(AU21:AW21) -> 3185000 | BN21: 84800 | BP21: =SUM(BE21:BO21) -> 3519800 | BQ21: 500000 | BR21: tambahan masak smp | BS21: =BD21-BP21+BQ21 -> 3820000 | BT21: 7106921207
A22: 16 | B22: SLP016 | C22: AA16 | D22: 216.084 | E22: SDIT | F22: Bandung, 10 April 1992 | G22: Februari | H22: 9 Agustus 2016 | I22: 8 | J22: TETAP | K22: BM | L22: S1 | M22: IIB | N22: IIB1 | O22: =VLOOKUP(P22,'TJ. FUNGSIONAL'!$B$4:$C$34,2,0) -> Wakil Kepala SD | P22: WAD | Q22: 18 | R22: 18 | W22: 2 | AI22: 2 | AK22: =VLOOKUP(N22,Gapok!$B$5:$I$94,6,0) -> 1925000 | AL22: =VLOOKUP(P22,'TJ. FUNGSIONAL'!$B$4:$F$34,5,0) -> 1700000 | AM22: =IF(R22+S22>=Q22,VLOOKUP(N22,Gapok!$B$5:$I$94,8,0),VLOOKUP('PER UNIT'!N22,Gapok!$B$5:$I$94,7,0)*('PER UNIT'!R22+'PER UNIT'!S22)) -> 475000 | AN22: =VLOOKUP(P22,'TJ. FUNGSIONAL'!$B$4:$E$34,4,0) -> 500000 | AO22: =50000*I22 -> 400000 | AP22: 35000 | AQ22: =(W22*25000)+X22*75000+Y22*25000+AH22*100000+AI22*50000+AJ22*30000 -> 150000 | AR22: =Z22*30000+AA22*50000 -> 0 | AS22: =25000*AF22 -> 0 | BB22: 975000 | BC22: 84800 | BD22: =SUM(AK22:BC22) -> 6244800 | BE22: =T22*25000+U22*40000+V22*60000 -> 0 | BF22: =7500*S22 -> 0 | BG22: =250000*AD22+175000*AE22 -> 0 | BH22: 35000 | BI22: 0 | BK22: 40000 | BL22: =SUM(AU22:AW22) -> 0 | BM22: 975000 | BN22: 84800 | BP22: =SUM(BE22:BO22) -> 1134800 | BS22: =BD22-BP22+BQ22 -> 5110000 | BT22: 7106921363
A23: 17 | B23: SLP017 | C23: AA17 | D23: 216.083 | E23: SDIT | F23: Gumaranga, 09 Maret 1992 | G23: Februari | H23: 10 Agustus 2016 | I23: 8 | J23: TETAP | K23: BM | L23: S1 | M23: IIB | N23: IIB1 | O23: =VLOOKUP(P23,'TJ. FUNGSIONAL'!$B$4:$C$34,2,0) -> Wakil Kepala SD | P23: WAD | Q23: 18 | R23: 12 | S23: 6 | W23: 2 | AE23: 1 | AK23: =VLOOKUP(N23,Gapok!$B$5:$I$94,6,0) -> 1925000 | AL23: =VLOOKUP(P23,'TJ. FUNGSIONAL'!$B$4:$F$34,5,0) -> 1700000 | AM23: =IF(R23+S23>=Q23,VLOOKUP(N23,Gapok!$B$5:$I$94,8,0),VLOOKUP('PER UNIT'!N23,Gapok!$B$5:$I$94,7,0)*('PER UNIT'!R23+'PER UNIT'!S23)) -> 475000 | AN23: =VLOOKUP(P23,'TJ. FUNGSIONAL'!$B$4:$E$34,4,0) -> 500000 | AO23: =50000*I23 -> 400000 | AP23: 105000 | AQ23: =(W23*25000)+X23*75000+Y23*25000+AH23*100000+AI23*50000+AJ23*30000 -> 50000 | AR23: =Z23*30000+AA23*50000 -> 0 | AS23: =25000*AF23 -> 0 | AU23: 685000 | BB23: 975000 | BC23: 84800 | BD23: =SUM(AK23:BC23) -> 6899800 | BE23: =T23*25000+U23*40000+V23*60000 -> 0 | BF23: =7500*S23 -> 45000 | BG23: =250000*AD23+175000*AE23 -> 175000 | BH23: 105000 | BI23: 0 | BK23: 40000 | BL23: =SUM(AU23:AW23) -> 685000 | BM23: 975000 | BN23: 84800 | BP23: =SUM(BE23:BO23) -> 2109800 | BS23: =BD23-BP23+BQ23 -> 4790000 | BT23: 7106921266
A24: 18 | B24: SLP018 | C24: AA18 | D24: 217.097 | E24: SDIT | F24: Bengkulu, 29 September 1990 | G24: Februari | H24: 13 Juni 2017 | I24: 8 | J24: TETAP | K24: M3 | L24: S1 | M24: IC | N24: IC1 | O24: =VLOOKUP(P24,'TJ. FUNGSIONAL'!$B$4:$C$34,2,0) -> Wali Kelas SD | P24: WKD | Q24: 18 | R24: 13 | S24: 5 | W24: 2 | AE24: 2 | AK24: =VLOOKUP(N24,Gapok!$B$5:$I$94,6,0) -> 1350000 | AL24: =VLOOKUP(P24,'TJ. FUNGSIONAL'!$B$4:$F$34,5,0) -> 1200000 | AM24: =IF(R24+S24>=Q24,VLOOKUP(N24,Gapok!$B$5:$I$94,8,0),VLOOKUP('PER UNIT'!N24,Gapok!$B$5:$I$94,7,0)*('PER UNIT'!R24+'PER UNIT'!S24)) -> 425000 | AN24: =VLOOKUP(P24,'TJ. FUNGSIONAL'!$B$4:$E$34,4,0) -> 300000 | AO24: =50000*I24 -> 400000 | AP24: 35000 | AQ24: =(W24*25000)+X24*75000+Y24*25000+AH24*100000+AI24*50000+AJ24*30000 -> 50000 | AR24: =Z24*30000+AA24*50000 -> 0 | AS24: =25000*AF24 -> 0 | AU24: 1370000 | AV24: 1000000 | BB24: 975000 | BC24: 84800 | BD24: =SUM(AK24:BC24) -> 7189800 | BE24: =T24*25000+U24*40000+V24*60000 -> 0 | BF24: =7500*S24 -> 37500 | BG24: =250000*AD24+175000*AE24 -> 350000 | BH24: 35000 | BI24: 0 | BK24: 40000 | BL24: =SUM(AU24:AW24) -> 2370000 | BM24: 975000 | BN24: 84800 | BP24: =SUM(BE24:BO24) -> 3892300 | BS24: =BD24-BP24+BQ24 -> 3297500 | BT24: 7112592932
A25: 19 | B25: SLP019 | C25: AA19 | D25: 217.100 | E25: SDIT | F25: Sleman, 17 April 1971 | G25: Februari | H25: 24 Juli 2017 | I25: 8 | J25: TETAP | K25: M4 | L25: SMA | M25: IA | N25: IA5 | O25: =VLOOKUP(P25,'TJ. FUNGSIONAL'!$B$4:$C$34,2,0) -> Petugas Kebersihan | P25: PKD | Q25: 21 | R25: 21 | AK25: =VLOOKUP(N25,Gapok!$B$5:$I$94,6,0) -> 900000 | AL25: =VLOOKUP(P25,'TJ. FUNGSIONAL'!$B$4:$F$34,5,0) -> 400000 | AM25: =IF(R25+S25>=Q25,VLOOKUP(N25,Gapok!$B$5:$I$94,8,0),VLOOKUP('PER UNIT'!N25,Gapok!$B$5:$I$94,7,0)*('PER UNIT'!R25+'PER UNIT'!S25)) -> 375000 | AN25: =VLOOKUP(P25,'TJ. FUNGSIONAL'!$B$4:$E$34,4,0) -> 300000 | AO25: =50000*I25 -> 400000 | AP25: 35000 | AQ25: =(W25*25000)+X25*75000+Y25*25000+AH25*100000+AI25*50000+AJ25*30000 -> 0 | AR25: =Z25*30000+AA25*50000 -> 0 | AS25: =25000*AF25 -> 0 | BD25: =SUM(AK25:BC25) -> 2410000 | BE25: =T25*25000+U25*40000+V25*60000 -> 0 | BF25: =7500*S25 -> 0 | BG25: =250000*AD25+175000*AE25 -> 0 | BH25: 0 | BI25: 0 | BL25: =SUM(AU25:AW25) -> 0 | BP25: =SUM(BE25:BO25) -> 0 | BS25: =BD25-BP25+BQ25 -> 2410000 | BT25: 7111989437
A26: 20 | B26: SLP020 | C26: AA20 | D26: 217.102 | E26: SDIT | F26: Magetan, 05 Mei 1974 | G26: Februari | H26: 43057 | I26: 7 | J26: TETAP | K26: M4 | L26: SMA | M26: IA | N26: IA3 | O26: =VLOOKUP(P26,'TJ. FUNGSIONAL'!$B$4:$C$34,2,0) -> Petugas Keamanan | P26: PKY | Q26: 28 | R26: 28 | AA26: 5 | AF26: 21 | AK26: =VLOOKUP(N26,Gapok!$B$5:$I$94,6,0) -> 850000 | AL26: =VLOOKUP(P26,'TJ. FUNGSIONAL'!$B$4:$F$34,5,0) -> 1200000 | AM26: =IF(R26+S26>=Q26,VLOOKUP(N26,Gapok!$B$5:$I$94,8,0),VLOOKUP('PER UNIT'!N26,Gapok!$B$5:$I$94,7,0)*('PER UNIT'!R26+'PER UNIT'!S26)) -> 375000 | AN26: =VLOOKUP(P26,'TJ. FUNGSIONAL'!$B$4:$E$34,4,0) -> 300000 | AO26: =50000*I26 -> 350000 | AP26: 35000 | AR26: =Z26*30000+AA26*50000 -> 250000 | AS26: =25000*AF26 -> 525000 | BD26: =SUM(AK26:BC26) -> 3885000 | BE26: =T26*25000+U26*40000+V26*60000 -> 0 | BF26: =7500*S26 -> 0 | BG26: =250000*AD26+175000*AE26 -> 0 | BH26: 0 | BI26: 0 | BL26: =SUM(AU26:AW26) -> 0 | BP26: =SUM(BE26:BO26) -> 0 | BS26: =BD26-BP26+BQ26 -> 3885000 | BT26: 7122991487
A27: 21 | B27: SLP021 | C27: AA21 | D27: 218.116 | E27: SDIT | F27: Kendal, 19 Januari 1993 | G27: Februari | H27: 16 Juli 2018 | I27: 7 | J27: TETAP | K27: BM | L27: S1 | M27: IC | N27: IC5 | O27: =VLOOKUP(P27,'TJ. FUNGSIONAL'!$B$4:$C$34,2,0) -> Wakil Kepala SD | P27: WADD | Q27: 18 | R27: 18 | W27: 2 | AH27: 2 | AK27: =VLOOKUP(N27,Gapok!$B$5:$I$94,6,0) -> 1450000 | AL27: =VLOOKUP(P27,'TJ. FUNGSIONAL'!$B$4:$F$34,5,0) -> 1500000 | AM27: =IF(R27+S27>=Q27,VLOOKUP(N27,Gapok!$B$5:$I$94,8,0),VLOOKUP('PER UNIT'!N27,Gapok!$B$5:$I$94,7,0)*('PER UNIT'!R27+'PER UNIT'!S27)) -> 425000 | AN27: =VLOOKUP(P27,'TJ. FUNGSIONAL'!$B$4:$E$34,4,0) -> 400000 | AO27: =50000*I27 -> 350000 | AP27: 70000 | AQ27: 250000 | AR27: =Z27*30000+AA27*50000 -> 0 | AS27: =25000*AF27 -> 0 | BB27: 975000 | BC27: 84800 | BD27: =SUM(AK27:BC27) -> 5504800 | BE27: =T27*25000+U27*40000+V27*60000 -> 0 | BF27: =7500*S27 -> 0 | BG27: =250000*AD27+175000*AE27 -> 0 | BH27: 70000 | BI27: 500000 | BK27: 40000 | BL27: =SUM(AU27:AW27) -> 0 | BM27: 975000 | BN27: 84800 | BP27: =SUM(BE27:BO27) -> 1669800 | BS27: =BD27-BP27+BQ27 -> 3835000 | BT27: 7122990488
A28: 22 | B28: SLP022 | C28: AA22 | D28: 219.136 | E28: SDIT | F28: Pekauman Kulon, 16 Juni 1990 | G28: Februari | H28: 15 Oktober 2019 | I28: 5 | J28: TETAP | K28: BM | L28: S1 | M28: IC | N28: IC1 | O28: =VLOOKUP(P28,'TJ. FUNGSIONAL'!$B$4:$C$34,2,0) -> Wakil Kepala SD | P28: WADD | Q28: 18 | R28: 18 | W28: 2 | AK28: =VLOOKUP(N28,Gapok!$B$5:$I$94,6,0) -> 1350000 | AL28: =VLOOKUP(P28,'TJ. FUNGSIONAL'!$B$4:$F$34,5,0) -> 1500000 | AM28: =IF(R28+S28>=Q28,VLOOKUP(N28,Gapok!$B$5:$I$94,8,0),VLOOKUP('PER UNIT'!N28,Gapok!$B$5:$I$94,7,0)*('PER UNIT'!R28+'PER UNIT'!S28)) -> 425000 | AN28: =VLOOKUP(P28,'TJ. FUNGSIONAL'!$B$4:$E$34,4,0) -> 400000 | AO28: =50000*I28 -> 250000 | AP28: 35000 | AQ28: =(W28*25000)+X28*75000+Y28*25000+AH28*100000+AI28*50000+AJ28*30000 -> 50000 | AR28: =Z28*30000+AA28*50000 -> 0 | AS28: =25000*AF28 -> 0 | BB28: 975000 | BC28: 84800 | BD28: =SUM(AK28:BC28) -> 5069800 | BE28: =T28*25000+U28*40000+V28*60000 -> 0 | BF28: =7500*S28 -> 0 | BG28: =250000*AD28+175000*AE28 -> 0 | BH28: 35000 | BI28: 0 | BK28: 40000 | BL28: =SUM(AU28:AW28) -> 0 | BM28: 975000 | BN28: 84800 | BP28: =SUM(BE28:BO28) -> 1134800 | BS28: =BD28-BP28+BQ28 -> 3935000 | BT28: 7135663594
A29: 23 | B29: SLP023 | C29: AA23 | D29: 219.140 | E29: SDIT | F29: Kumpulan, 23 Desember 1993 | G29: Februari | H29: 15 Oktober 2019 | I29: 5 | J29: TETAP | K29: BM | L29: S1 | M29: IB | N29: IC1 | O29: =VLOOKUP(P29,'TJ. FUNGSIONAL'!$B$4:$C$34,2,0) -> Guru Mapel SD | P29: GMD | Q29: 18 | R29: 17 | S29: 1 | W29: 2 | AH29: 2 | AK29: =VLOOKUP(N29,Gapok!$B$5:$I$94,6,0) -> 1350000 | AL29: =VLOOKUP(P29,'TJ. FUNGSIONAL'!$B$4:$F$34,5,0) -> 900000 | AM29: =IF(R29+S29>=Q29,VLOOKUP(N29,Gapok!$B$5:$I$94,8,0),VLOOKUP('PER UNIT'!N29,Gapok!$B$5:$I$94,7,0)*('PER UNIT'!R29+'PER UNIT'!S29)) -> 425000 | AN29: =VLOOKUP(P29,'TJ. FUNGSIONAL'!$B$4:$E$34,4,0) -> 300000 | AO29: =50000*I29 -> 250000 | AP29: 35000 | AQ29: =(W29*25000)+X29*75000+Y29*25000+AH29*100000+AI29*50000+AJ29*30000 -> 250000 | AR29: =Z29*30000+AA29*50000 -> 0 | AS29: =25000*AF29 -> 0 | BB29: 975000 | BC29: 84800 | BD29: =SUM(AK29:BC29) -> 4569800 | BE29: =T29*25000+U29*40000+V29*60000 -> 0 | BF29: =7500*S29 -> 7500 | BG29: =250000*AD29+175000*AE29 -> 0 | BH29: 35000 | BI29: 0 | BK29: 40000 | BL29: =SUM(AU29:AW29) -> 0 | BM29: 975000 | BN29: 84800 | BP29: =SUM(BE29:BO29) -> 1142300 | BS29: =BD29-BP29+BQ29 -> 3427500 | BT29: 7135663705
A30: 24 | B30: SLP024 | C30: AA24 | D30: 219.137 | E30: SDIT | F30: Dumai, 01 September 1994 | G30: Februari | H30: 15 Oktober 2019 | I30: 5 | J30: TETAP | K30: BM | L30: S2 | M30: IC | N30: IIA1 | O30: =VLOOKUP(P30,'TJ. FUNGSIONAL'!$B$4:$C$34,2,0) -> Wakil Kepala SD | P30: WADD | Q30: 8 | R30: 8 | AK30: =VLOOKUP(N30,Gapok!$B$5:$I$94,6,0) -> 1650000 | AL30: =VLOOKUP(P30,'TJ. FUNGSIONAL'!$B$4:$F$34,5,0) -> 1500000 | AM30: =8*18000 -> 144000 | AN30: =VLOOKUP(P30,'TJ. FUNGSIONAL'!$B$4:$E$34,4,0) -> 400000 | AO30: =50000*I30 -> 250000 | AP30: 35000 | AQ30: =(W30*25000)+X30*75000+Y30*25000+AH30*100000+AI30*50000+AJ30*30000 -> 0 | AR30: =Z30*30000+AA30*50000 -> 0 | AS30: =25000*AF30 -> 0 | AT30: 1000000 | AY30: Tim Media | BB30: 975000 | BC30: 84800 | BD30: =SUM(AK30:BC30) -> 6038800 | BE30: =T30*25000+U30*40000+V30*60000 -> 0 | BF30: =7500*S30 -> 0 | BG30: =250000*AD30+175000*AE30 -> 0 | BH30: 35000 | BI30: 0 | BK30: 40000 | BL30: =SUM(AU30:AW30) -> 0 | BM30: 975000 | BN30: 84800 | BP30: =SUM(BE30:BO30) -> 1134800 | BS30: =BD30-BP30+BQ30 -> 4904000 | BT30: 7135663675 | BU30: CUTI MELAHIRKAN
